import { DomainError } from '@domain/errors/DomainError';
import { logger } from '@shared/utils/logger';
import { NextFunction, Request, Response } from 'express';

export function errorHandler(error: Error, req: Request, res: Response, next: NextFunction) {
  // Log the error
  logger.error('Request error', {
    error: error.message,
    stack: error.stack,
    url: req.url,
    method: req.method,
    ip: req.ip,
    userAgent: req.get('User-Agent'),
    userId: req.user?.userId,
  });

  // Handle known domain errors
  if (error instanceof DomainError) {
    return res.status(error.statusCode).json({
      success: false,
      error: {
        code: error.code,
        message: error.message,
        details: error.details,
      },
    });
  }

  // Handle validation errors (though they should be DomainErrors now)
  if (error.name === 'ValidationError') {
    return res.status(400).json({
      success: false,
      error: {
        code: 'VALIDATION_ERROR',
        message: error.message,
        details: (error as any).details,
      },
    });
  }

  // Handle unexpected errors
  return res.status(500).json({
    success: false,
    error: {
      code: 'INTERNAL_SERVER_ERROR',
      message:
        process.env.NODE_ENV === 'production' ? 'An unexpected error occurred' : error.message,
    },
  });
}

export function notFoundHandler(req: Request, res: Response) {
  logger.warn('Route not found', {
    url: req.url,
    method: req.method,
    ip: req.ip,
  });

  res.status(404).json({
    success: false,
    error: {
      code: 'NOT_FOUND',
      message: `Route ${req.method} ${req.url} not found`,
    },
  });
}

// Async error wrapper to catch async errors in route handlers
export function asyncHandler(fn: Function) {
  return (req: Request, res: Response, next: NextFunction) => {
    Promise.resolve(fn(req, res, next)).catch(next);
  };
}
